ERROR 2021-01-06 21:29:38,545: report_part_c.docx does not exist.
INFO 2021-01-06 21:29:38,560: Successfully loaded benchmark labels data.
INFO 2021-01-06 21:29:38,560: Successfully loaded queries data.
INFO 2021-01-06 21:29:39,774: Successfully imported module search_engine_4.
DEBUG 2021-01-06 21:29:47,843: Building the index in search_engine_4 for benchmark data took 8.0745963 seconds.
ERROR 2021-01-06 21:30:07,873: The following error occured while testing the module search_engine_4.
ERROR 2021-01-06 21:30:07,873: 'module' object is not callable
Traceback (most recent call last):
  File "C:/Users/shaha/Desktop/Search_Engine-master/test_part_c_students.py", line 112, in <module>
    n_res, res = engine.search('bioweapon')
  File "C:\Users\shaha\Desktop\Search_Engine-master\search_engine_4.py", line 97, in search
    return searcher.search(query)
  File "C:\Users\shaha\Desktop\Search_Engine-master\searcher.py", line 38, in search
    relevant_docs, relevant_inverted_docs = self._relevant_docs_from_posting(query_as_list)
  File "C:\Users\shaha\Desktop\Search_Engine-master\searcher.py", line 71, in _relevant_docs_from_posting
    list_to_expand = self.Thesaurus_expansion(query_as_list, inv_idx)
  File "C:\Users\shaha\Desktop\Search_Engine-master\searcher.py", line 115, in Thesaurus_expansion
    word = Word()
TypeError: 'module' object is not callable
DEBUG 2021-01-06 21:30:07,873: Total runtime was: 0:00:29.327887
